[03/20/2025 11:19:13 PM:pyrogram.dispatcher:253:ERROR] Telegram says: [400 QUERY_ID_INVALID] - The callback query id is invalid (caused by "messages.SetBotCallbackAnswer")
Traceback (most recent call last):
  File "C:\Users\GBT B450M-S2H\AppData\Local\Packages\PythonSoftwareFoundation.Python.3.11_qbz5n2kfra8p0\LocalCache\local-packages\Python311\site-packages\pyrogram\dispatcher.py", line 240, in handler_worker
    await handler.callback(self.client, *args)
  File "C:\Users\GBT B450M-S2H\Documents\Film-robat-Tech_VJ\plugins\pm_filter.py", line 2576, in cb_handler
    await query.answer(MSG_ALRT)
  File "C:\Users\GBT B450M-S2H\AppData\Local\Packages\PythonSoftwareFoundation.Python.3.11_qbz5n2kfra8p0\LocalCache\local-packages\Python311\site-packages\pyrogram\types\bots_and_keyboards\callback_query.py", line 159, in answer
    return await self._client.answer_callback_query(
           ^^^^^^^^^^^^^^^^^^^^^^^^^^^^^^^^^^^^^^^^^
  File "C:\Users\GBT B450M-S2H\AppData\Local\Packages\PythonSoftwareFoundation.Python.3.11_qbz5n2kfra8p0\LocalCache\local-packages\Python311\site-packages\pyrogram\methods\bots\answer_callback_query.py", line 73, in answer_callback_query
    return await self.invoke(
           ^^^^^^^^^^^^^^^^^^
  File "C:\Users\GBT B450M-S2H\AppData\Local\Packages\PythonSoftwareFoundation.Python.3.11_qbz5n2kfra8p0\LocalCache\local-packages\Python311\site-packages\pyrogram\methods\advanced\invoke.py", line 79, in invoke
    r = await self.session.invoke(
        ^^^^^^^^^^^^^^^^^^^^^^^^^^
  File "C:\Users\GBT B450M-S2H\AppData\Local\Packages\PythonSoftwareFoundation.Python.3.11_qbz5n2kfra8p0\LocalCache\local-packages\Python311\site-packages\pyrogram\session\session.py", line 389, in invoke
    return await self.send(query, timeout=timeout)
           ^^^^^^^^^^^^^^^^^^^^^^^^^^^^^^^^^^^^^^^
  File "C:\Users\GBT B450M-S2H\AppData\Local\Packages\PythonSoftwareFoundation.Python.3.11_qbz5n2kfra8p0\LocalCache\local-packages\Python311\site-packages\pyrogram\session\session.py", line 357, in send
    RPCError.raise_it(result, type(data))
  File "C:\Users\GBT B450M-S2H\AppData\Local\Packages\PythonSoftwareFoundation.Python.3.11_qbz5n2kfra8p0\LocalCache\local-packages\Python311\site-packages\pyrogram\errors\rpc_error.py", line 91, in raise_it
    raise getattr(
pyrogram.errors.exceptions.bad_request_400.QueryIdInvalid: Telegram says: [400 QUERY_ID_INVALID] - The callback query id is invalid (caused by "messages.SetBotCallbackAnswer")
[03/20/2025 11:23:16 PM:pyrogram.dispatcher:253:ERROR] Telegram says: [400 MESSAGE_ID_INVALID] - The message id is invalid (caused by "messages.EditMessage")
Traceback (most recent call last):
  File "C:\Users\GBT B450M-S2H\AppData\Local\Packages\PythonSoftwareFoundation.Python.3.11_qbz5n2kfra8p0\LocalCache\local-packages\Python311\site-packages\pyrogram\dispatcher.py", line 240, in handler_worker
    await handler.callback(self.client, *args)
  File "C:\Users\GBT B450M-S2H\Documents\Film-robat-Tech_VJ\plugins\pm_filter.py", line 84, in pm_text
    await auto_filter(bot, content, message, reply_msg, ai_search)
  File "C:\Users\GBT B450M-S2H\Documents\Film-robat-Tech_VJ\plugins\pm_filter.py", line 2605, in auto_filter
    return await advantage_spell_chok(client, name, msg, reply_msg, ai_search)
           ^^^^^^^^^^^^^^^^^^^^^^^^^^^^^^^^^^^^^^^^^^^^^^^^^^^^^^^^^^^^^^^^^^^
  File "C:\Users\GBT B450M-S2H\Documents\Film-robat-Tech_VJ\plugins\pm_filter.py", line 2844, in advantage_spell_chok
    k = await reply_msg.edit_text(text=script.I_CUDNT.format(mv_rqst), reply_markup=InlineKeyboardMarkup(button))
        ^^^^^^^^^^^^^^^^^^^^^^^^^^^^^^^^^^^^^^^^^^^^^^^^^^^^^^^^^^^^^^^^^^^^^^^^^^^^^^^^^^^^^^^^^^^^^^^^^^^^^^^^^
  File "C:\Users\GBT B450M-S2H\AppData\Local\Packages\PythonSoftwareFoundation.Python.3.11_qbz5n2kfra8p0\LocalCache\local-packages\Python311\site-packages\pyrogram\types\messages_and_media\message.py", line 2803, in edit_text
    return await self._client.edit_message_text(
           ^^^^^^^^^^^^^^^^^^^^^^^^^^^^^^^^^^^^^
  File "C:\Users\GBT B450M-S2H\AppData\Local\Packages\PythonSoftwareFoundation.Python.3.11_qbz5n2kfra8p0\LocalCache\local-packages\Python311\site-packages\pyrogram\methods\messages\edit_message_text.py", line 82, in edit_message_text
    r = await self.invoke(
        ^^^^^^^^^^^^^^^^^^
  File "C:\Users\GBT B450M-S2H\AppData\Local\Packages\PythonSoftwareFoundation.Python.3.11_qbz5n2kfra8p0\LocalCache\local-packages\Python311\site-packages\pyrogram\methods\advanced\invoke.py", line 79, in invoke
    r = await self.session.invoke(
        ^^^^^^^^^^^^^^^^^^^^^^^^^^
  File "C:\Users\GBT B450M-S2H\AppData\Local\Packages\PythonSoftwareFoundation.Python.3.11_qbz5n2kfra8p0\LocalCache\local-packages\Python311\site-packages\pyrogram\session\session.py", line 389, in invoke
    return await self.send(query, timeout=timeout)
           ^^^^^^^^^^^^^^^^^^^^^^^^^^^^^^^^^^^^^^^
  File "C:\Users\GBT B450M-S2H\AppData\Local\Packages\PythonSoftwareFoundation.Python.3.11_qbz5n2kfra8p0\LocalCache\local-packages\Python311\site-packages\pyrogram\session\session.py", line 357, in send
    RPCError.raise_it(result, type(data))
  File "C:\Users\GBT B450M-S2H\AppData\Local\Packages\PythonSoftwareFoundation.Python.3.11_qbz5n2kfra8p0\LocalCache\local-packages\Python311\site-packages\pyrogram\errors\rpc_error.py", line 91, in raise_it
    raise getattr(
pyrogram.errors.exceptions.bad_request_400.MessageIdInvalid: Telegram says: [400 MESSAGE_ID_INVALID] - The message id is invalid (caused by "messages.EditMessage")
